Workbook

Sheet 01 Bezahlt
A1: Bereits gebuchte & bezahlte Kosten (Vorab-/Fixkosten)
A2: Flug, Mietwagen und alle Unterkünfte. Spalte »bezahlt« zählt nur tatsächlich geflossenes Geld, »offen« ist noch fällig.
A4: Nr | B4: Datum | C4: Kategorie | D4: Beschreibung | E4: Nächte | F4: Betrag € | G4: Status | H4: bezahlt € | I4: offen € | J4: Zahler | K4: Zahlmittel | L4: Anmerkung
A5: 1 | B5: 2026-09-02 | C5: Flug | D5: Flug Wien - Muenchen - Windhoek (2 Pers.) | F5: 1895.26 | G5: bezahlt | H5: 1895.26 | I5: 0 | J5: Nora | K5: N26 Debit | L5: Von Nora vorab beglichen
A6: 2 | B6: 2026-09-03 | C6: Mietwagen | D6: Mietwagen inkl. Camping-Ausstattung 03.-21.09. | F6: 2805 | G6: bezahlt | H6: 2805 | I6: 0 | J6: Patrick | K6: TBD | L6: BETRAG UNKLAR: 2805.00 (DE-Tab) vs 2605.03 (Altversion) - bitte klaeren
A7: 3 | B7: 2026-09-03 | C7: Unterkunft | D7: Kalahari Anib Campsite | E7: 1 | F7: 36 | G7: vor Ort - bestaetigen | H7: 0 | I7: 36 | J7: TBD | K7: Bargeld? | L7: Nacht bereits vergangen - wer hat gezahlt?
A8: 4 | B8: 2026-09-04 | C8: Unterkunft | D8: Quiver Tree Camping | E8: 1 | F8: 0 | G8: bar bezahlt - siehe Blatt 02 | H8: 0 | I8: 0 | J8: Patrick | K8: Bargeld | L8: 720 NAD bar von Patrick gezahlt - Betrag steht in Blatt 02 Nr. 8 (keine Doppelzaehlung)
A9: 5 | B9: 2026-09-05 | C9: Unterkunft | D9: Desert Horse Campsite Aus | E9: 2 | F9: 24 | G9: Deposit bezahlt - Rest siehe Blatt 02 | H9: 24 | I9: 0 | J9: Nora | K9: N26 Debit | L9: Restzahlung 100.91 EUR am 05.09. an Klein Aus Vista Lodge - steht in Blatt 02 Nr. 11
A10: 6 | B10: 2026-09-07 | C10: Unterkunft | D10: Wereldend Mountain Campsite | E10: 1 | F10: 47.8 | G10: offen - cash on arrival | H10: 0 | I10: 47.8 | J10: TBD | K10: Bargeld | L10: Bar vor Ort faellig
A11: 7 | B11: 2026-09-08 | C11: Unterkunft | D11: Little Sossus Campsite | E11: 2 | F11: 84 | G11: offen | H11: 0 | I11: 84 | J11: TBD | K11: TBD | L11: Zahlung ausstaendig
A12: 8 | B12: 2026-09-10 | C12: Unterkunft | D12: Moonvalley River Camp Swakopmund | E12: 1 | F12: 25 | G12: offen - cash on arrival | H12: 0 | I12: 25 | J12: TBD | K12: Bargeld | L12: Bar vor Ort faellig
A13: 9 | B13: 2026-09-11 | C13: Unterkunft | D13: Spitzkoppe Campsite | E13: 2 | F13: 62 | G13: offen | H13: 0 | I13: 62 | J13: TBD | K13: TBD | L13: Zahlung ausstaendig
A14: 10 | B14: 2026-09-13 | C14: Unterkunft | D14: Granietkop Campsite Damaraland | E14: 1 | F14: 48 | G14: gebucht - Status unklar | H14: 0 | I14: 48 | J14: TBD | K14: TBD | L14: Zahlungsstatus bitte pruefen
A15: 11 | B15: 2026-09-14 | C15: Unterkunft | D15: Hoada Campsite (statt Ugab Terrace) | E15: 1 | F15: 45 | G15: angezahlt | H15: 0 | I15: 45 | J15: Nora | K15: N26 Debit | L15: Anzahlungsbetrag unbekannt - bitte nachtragen
A16: 12 | B16: 2026-09-15 | C16: Unterkunft | D16: Okaukuejo Campsite Etosha | E16: 1 | F16: 58 | G16: bezahlt | H16: 58 | I16: 0 | J16: Nora | K16: N26 Debit | L16: Von Nora vorab beglichen
A17: 13 | B17: 2026-09-16 | C17: Unterkunft | D17: Halali Campsite Etosha | E17: 1 | F17: 57 | G17: bezahlt | H17: 57 | I17: 0 | J17: Nora | K17: N26 Debit | L17: Von Nora vorab beglichen
A18: 14 | B18: 2026-09-17 | C18: Unterkunft | D18: Onguma Tamboti | E18: 1 | F18: 58 | G18: gebucht - Status unklar | H18: 0 | I18: 58 | J18: TBD | K18: TBD | L18: Zahlungsstatus bitte pruefen
... A21: 17 | B21: 2026-09-20 | C21: Unterkunft | D21: Omatozu Safari Camp | E21: 1 | F21: 34 | G21: bezahlt | H21: 34 | I21: 0 | J21: Nora | K21: N26 Debit | L21: Von Nora vorab beglichen
D22: SUMME | F22: =SUM(F5:F21) | H22: =SUM(H5:H21) | I22: =SUM(I5:I21)

Sheet 02 Laufend
A1: Laufende Kosten während der Reise
A2: Typ »Ausgabe« = echte Kosten. Typ »Abhebung« = Umbuchung in die Reisekasse (keine Ausgabe!). Kurs = Fremdwährung ÷ Euro.
A4: Nr | B4: Datum | C4: Zeit | D4: Typ | E4: Ort | F4: Händler | G4: Kategorie | H4: Betrag FW | I4: Währung | J4: Betrag € | K4: Zahler | L4: Zahlmittel | M4: Kurs NAD/€ | N4: Anmerkung
A5: 1 | B5: 2026-09-02 | C5: 14:14 | D5: Ausgabe | E5: Flughafen Wien | F5: Leberkaespepi | G5: Restaurant | I5: EUR | J5: 9.8 | K5: Patrick | L5: Oberbank Debit? | M5: =IF(AND(H5<>"",J5<>"",J5<>0),H5/J5,"") | N5: Verpflegung Anreise
A6: 2 | B6: 2026-09-02 | C6: 15:03 | D6: Ausgabe | E6: Flughafen Wien | F6: Relay F Gate | G6: Sonstiges | I6: EUR | J6: 11.84 | K6: Patrick | L6: Oberbank Debit? | M6: =IF(AND(H6<>"",J6<>"",J6<>0),H6/J6,"") | N6: Kiosk - Kategorie bitte bestaetigen
A7: 3 | B7: 2026-09-02 | C7: 20:05 | D7: Ausgabe | E7: Flughafen Muenchen | F7: MUC Airport Retail | G7: Sonstiges | I7: EUR | J7: 5.91 | K7: Patrick | L7: Oberbank Debit? | M7: =IF(AND(H7<>"",J7<>"",J7<>0),H7/J7,"") | N7: Transit MUC
A8: 4 | B8: 2026-09-03 | C8: 09:08 | D8: Abhebung | E8: Windhoek | F8: ATM WHKHKC01 | G8: Bargeld | H8: 4047 | I8: NAD | J8: 217.2 | K8: Patrick | L8: Oberbank Debit | M8: =IF(AND(H8<>"",J8<>"",J8<>0),H8/J8,"") | N8: Bargeldbezug in die Reisekasse - KEINE Ausgabe
A9: 5 | B9: 2026-09-03 | C9: 09:08 | D9: Ausgabe | E9: Windhoek | F9: ATM Behebungsentgelt | G9: Gebühren | I9: EUR | J9: 2.52 | K9: Patrick | L9: Oberbank Debit | M9: =IF(AND(H9<>"",J9<>"",J9<>0),H9/J9,"") | N9: Entgelt zur Abhebung Nr. 4
A10: 6 | B10: 2026-09-03 | C10: 12:26 | D10: Ausgabe | E10: Windhoek | F10: Superspar Maerua Mall | G10: Lebensmittel | H10: 3122.63 | I10: NAD | J10: 169.22 | K10: Patrick | L10: Oberbank Debit? | M10: =IF(AND(H10<>"",J10<>"",J10<>0),H10/J10,"") | N10: Grosseinkauf Camping-Proviant
A11: 7 | B11: 2026-09-03 | C11: 13:51 | D11: Ausgabe | E11: Rehoboth | F11: Agrimark Rehoboth Express | G11: Ausrüstung | H11: 1343.3 | I11: NAD | J11: 73.42 | K11: Patrick | L11: Oberbank Debit? | M11: =IF(AND(H11<>"",J11<>"",J11<>0),H11/J11,"") | N11: KATEGORIE UNKLAR - Agrimark = Landhandel (Gas/Holz/Ausruestung/Lebensmittel?)
A12: 8 | B12: 2026-09-05 | D12: Ausgabe | E12: Quiver Tree Forest | F12: Quivertree Forest Camping | G12: Unterkunft | H12: 720 | I12: NAD | J12: 38.64 | K12: Patrick | L12: Bargeld | M12: =IF(AND(H12<>"",J12<>"",J12<>0),H12/J12,"") | N12: Bar aus der Reisekasse; EUR zum ATM-Kurs 18.633 NAD/EUR umgerechnet
A13: 9 | B13: 2026-09-04 | C13: 11:58 | D13: Ausgabe | E13: Mariental | F13: Spar Mariental | G13: Lebensmittel | I13: EUR | J13: 20.11 | K13: Nora | L13: N26 Debit | M13: =IF(AND(H13<>"",J13<>"",J13<>0),H13/J13,"")
A14: 10 | B14: 2026-09-05 | C14: 12:19 | D14: Ausgabe | E14: Keetmanshoop | F14: Agra Keetmanshoop - Fo | G14: Tanken | I14: EUR | J14: 98.15 | K14: Nora | L14: N26 Debit | M14: =IF(AND(H14<>"",J14<>"",J14<>0),H14/J14,"") | N14: KATEGORIE ZU BESTAETIGEN - Agra ist Landhandel mit Tankstelle; N26 kategorisiert als Transport & Auto
A15: 11 | B15: 2026-09-05 | C15: 15:00 | D15: Ausgabe | E15: Aus | F15: Klein Aus Vista Lodge | G15: Unterkunft | I15: EUR | J15: 100.91 | K15: Nora | L15: N26 Debit | M15: =IF(AND(H15<>"",J15<>"",J15<>0),H15/J15,"") | N15: BETRAG PRUEFEN - Restzahlung Desert Horse Campsite (2 Naechte); geplant waren 48 EUR gesamt inkl. 24 EUR Deposit
A16: 12 | B16: 2026-09-06 | C16: 08:24 | D16: Ausgabe | E16: Kolmanskop | F16: Ghost Town Tours CC | G16: Aktivitäten | I16: EUR | J16: 24.96 | K16: Nora | L16: N26 Debit | M16: =IF(AND(H16<>"",J16<>"",J16<>0),H16/J16,"") | N16: Geisterstadt-Tour Kolmanskop
A17: 13 | B17: 2026-09-06 | C17: 11:24 | D17: Ausgabe | E17: Aus | F17: Desert Deli | G17: Restaurant | I17: EUR | J17: 4.72 | K17: Nora | L17: N26 Debit | M17: =IF(AND(H17<>"",J17<>"",J17<>0),H17/J17,"")
A18: 14 | B18: 2026-09-06 | C18: 12:46 | D18: Ausgabe | E18: Lüderitz | F18: Portugues Fisherman | G18: Restaurant | I18: EUR | J18: 45.57 | K18: Nora | L18: N26 Debit | M18: =IF(AND(H18<>"",J18<>"",J18<>0),H18/J18,"")
A19: 15 | B19: 2026-09-06 | C19: 13:43 | D19: Ausgabe | E19: Lüderitz | F19: Spar Lüderitz | G19: Lebensmittel | I19: EUR | J19: 38.38 | K19: Nora | L19: N26 Debit | M19: =IF(AND(H19<>"",J19<>"",J19<>0),H19/J19,"")
A20: 16 | B20: 2026-09-06 | C20: 13:54 | D20: Ausgabe | E20: Lüderitz | F20: Studio88 Lüderitz | G20: Shopping | I20: EUR | J20: 20.07 | K20: Nora | L20: N26 Debit | M20: =IF(AND(H20<>"",J20<>"",J20<>0),H20/J20,"")
A21: 17 | B21: 2026-09-06 | C21: 14:19 | D21: Ausgabe | E21: Lüderitz | F21: Lüderitz Fuel Center | G21: Tanken | I21: EUR | J21: 60.2 | K21: Nora | L21: N26 Debit | M21: =IF(AND(H21<>"",J21<>"",J21<>0),H21/J21,"")
M22: =IF(AND(H22<>"",J22<>"",J22<>0),H22/J22,"")
M23: =IF(AND(H23<>"",J23<>"",J23<>0),H23/J23,"")
M24: =IF(AND(H24<>"",J24<>"",J24<>0),H24/J24,"")
M25: =IF(AND(H25<>"",J25<>"",J25<>0),H25/J25,"")
M26: =IF(AND(H26<>"",J26<>"",J26<>0),H26/J26,"")
M27: =IF(AND(H27<>"",J27<>"",J27<>0),H27/J27,"")
M28: =IF(AND(H28<>"",J28<>"",J28<>0),H28/J28,"")
M29: =IF(AND(H29<>"",J29<>"",J29<>0),H29/J29,"")
M30: =IF(AND(H30<>"",J30<>"",J30<>0),H30/J30,"")
M31: =IF(AND(H31<>"",J31<>"",J31<>0),H31/J31,"")
M32: =IF(AND(H32<>"",J32<>"",J32<>0),H32/J32,"")
M33: =IF(AND(H33<>"",J33<>"",J33<>0),H33/J33,"")
... M81: =IF(AND(H81<>"",J81<>"",J81<>0),H81/J81,"")
F82: SUMME echte Ausgaben (Typ = Ausgabe) | J82: =SUMIFS(J5:J81,D5:D81,"Ausgabe")

Sheet 03 Zusammenfassung
A1: Zusammenfassung Namibia 2026
A2: Alle Werte sind Formeln – sie aktualisieren sich, sobald du auf Blatt 1 oder 2 etwas änderst.
A5: Kosten nach Kategorie | F5: Vorab = Blatt 01, Laufend = Blatt 02 (nur Typ »Ausgabe«)
A6: Kategorie | B6: Vorab € | C6: Laufend € | D6: Gesamt €
A7: Flug | B7: =SUMIF('01 Bezahlt'!C5:C21,A7,'01 Bezahlt'!F5:F21) | C7: =SUMIFS('02 Laufend'!J5:J81,'02 Laufend'!G5:G81,A7,'02 Laufend'!D5:D81,"Ausgabe") | D7: =B7+C7
A8: Mietwagen | B8: =SUMIF('01 Bezahlt'!C5:C21,A8,'01 Bezahlt'!F5:F21) | C8: =SUMIFS('02 Laufend'!J5:J81,'02 Laufend'!G5:G81,A8,'02 Laufend'!D5:D81,"Ausgabe") | D8: =B8+C8
A9: Unterkunft | B9: =SUMIF('01 Bezahlt'!C5:C21,A9,'01 Bezahlt'!F5:F21) | C9: =SUMIFS('02 Laufend'!J5:J81,'02 Laufend'!G5:G81,A9,'02 Laufend'!D5:D81,"Ausgabe") | D9: =B9+C9
A10: Tanken | B10: =SUMIF('01 Bezahlt'!C5:C21,A10,'01 Bezahlt'!F5:F21) | C10: =SUMIFS('02 Laufend'!J5:J81,'02 Laufend'!G5:G81,A10,'02 Laufend'!D5:D81,"Ausgabe") | D10: =B10+C10
A11: Lebensmittel | B11: =SUMIF('01 Bezahlt'!C5:C21,A11,'01 Bezahlt'!F5:F21) | C11: =SUMIFS('02 Laufend'!J5:J81,'02 Laufend'!G5:G81,A11,'02 Laufend'!D5:D81,"Ausgabe") | D11: =B11+C11
A12: Restaurant | B12: =SUMIF('01 Bezahlt'!C5:C21,A12,'01 Bezahlt'!F5:F21) | C12: =SUMIFS('02 Laufend'!J5:J81,'02 Laufend'!G5:G81,A12,'02 Laufend'!D5:D81,"Ausgabe") | D12: =B12+C12
A13: Eintritt | B13: =SUMIF('01 Bezahlt'!C5:C21,A13,'01 Bezahlt'!F5:F21) | C13: =SUMIFS('02 Laufend'!J5:J81,'02 Laufend'!G5:G81,A13,'02 Laufend'!D5:D81,"Ausgabe") | D13: =B13+C13
A14: Aktivitäten | B14: =SUMIF('01 Bezahlt'!C5:C21,A14,'01 Bezahlt'!F5:F21) | C14: =SUMIFS('02 Laufend'!J5:J81,'02 Laufend'!G5:G81,A14,'02 Laufend'!D5:D81,"Ausgabe") | D14: =B14+C14
A15: Ausrüstung | B15: =SUMIF('01 Bezahlt'!C5:C21,A15,'01 Bezahlt'!F5:F21) | C15: =SUMIFS('02 Laufend'!J5:J81,'02 Laufend'!G5:G81,A15,'02 Laufend'!D5:D81,"Ausgabe") | D15: =B15+C15
A16: Gebühren | B16: =SUMIF('01 Bezahlt'!C5:C21,A16,'01 Bezahlt'!F5:F21) | C16: =SUMIFS('02 Laufend'!J5:J81,'02 Laufend'!G5:G81,A16,'02 Laufend'!D5:D81,"Ausgabe") | D16: =B16+C16
A17: Shopping | B17: =SUMIF('01 Bezahlt'!C5:C21,A17,'01 Bezahlt'!F5:F21) | C17: =SUMIFS('02 Laufend'!J5:J81,'02 Laufend'!G5:G81,A17,'02 Laufend'!D5:D81,"Ausgabe") | D17: =B17+C17
A18: Sonstiges | B18: =SUMIF('01 Bezahlt'!C5:C21,A18,'01 Bezahlt'!F5:F21) | C18: =SUMIFS('02 Laufend'!J5:J81,'02 Laufend'!G5:G81,A18,'02 Laufend'!D5:D81,"Ausgabe") | D18: =B18+C18
A19: GESAMT | B19: =SUM(B7:B18) | C19: =SUM(C7:C18) | D19: =SUM(D7:D18)
A22: Zahlungsstand Vorabkosten
A23: bereits bezahlt | C23: =SUM('01 Bezahlt'!H5:H21)
A24: noch offen | C24: =SUM('01 Bezahlt'!I5:I21) | E24: davon einige bar vor Ort fällig
A27: Wer hat wie viel getragen | F27: »Kasse« = bar aus der gemeinsamen Reisekasse
A28: Patrick – Vorabkosten | C28: =SUMIF('01 Bezahlt'!J5:J21,"Patrick",'01 Bezahlt'!H5:H21)
A29: Patrick – laufend (Karte) | C29: =SUMIFS('02 Laufend'!J5:J81,'02 Laufend'!K5:K81,"Patrick",'02 Laufend'!D5:D81,"Ausgabe")
A30: Nora – Vorabkosten | C30: =SUMIF('01 Bezahlt'!J5:J21,"Nora",'01 Bezahlt'!H5:H21)
A31: Nora – laufend (Karte) | C31: =SUMIFS('02 Laufend'!J5:J81,'02 Laufend'!K5:K81,"Nora",'02 Laufend'!D5:D81,"Ausgabe")
A32: aus Reisekasse (bar) | C32: =SUMIFS('02 Laufend'!J5:J81,'02 Laufend'!K5:K81,"Kasse",'02 Laufend'!D5:D81,"Ausgabe") | E32: Einleger der Kasse: siehe Abschnitt Reisekasse
A33: noch ungeklärt (TBD) | C33: =SUMIF('01 Bezahlt'!J5:J21,"TBD",'01 Bezahlt'!H5:H21)+SUMIFS('02 Laufend'!J5:J81,'01 Bezahlt'!J5:J21,"TBD",'02 Laufend'!D5:D81,"Ausgabe") | E33: muss auf Patrick oder Nora aufgelöst werden
A36: Reisekasse (Bargeld) | F36: Abhebungen sind keine Ausgaben – nur Umbuchung
A37: abgehoben gesamt | C37: =SUMIFS('02 Laufend'!J5:J81,'02 Laufend'!D5:D81,"Abhebung")
A38: davon bar ausgegeben | C38: =SUMIFS('02 Laufend'!J5:J81,'02 Laufend'!D5:D81,"Ausgabe",'02 Laufend'!L5:L81,"Bargeld")
A39: Kassenbestand rechnerisch | C39: =C37-C38
A40: Kassenbestand tatsächlich | E40: hier den gezählten Bestand eintragen →
A43: Verrechnung zwischen Patrick und Nora
A44: Überweisung Patrick → Nora (TBD) | C44: 2000 | E44: Ausgleich fuer Noras Vorauszahlungen (Flug + Unterkuenfte)
A45: Beitrag Patrick (Karte + Kasse + Überweisung) | C45: =C28+C29+C32+C44 | E45: Kasse zählt zu Patrick, solange nur er abhebt
A46: Beitrag Nora (Karte) | C46: =C30+C31
A47: Gesamtausgaben | C47: =D19
A48: Anteil je Person (50/50) | C48: =C47/2
A49: Saldo Patrick ohne Überweisung | C49: =C45-C44-C48 | E49: rein aus getragenen Kosten – so viel hat Patrick zu viel bezahlt
A50: Saldo Patrick gesamt | C50: =C45-C48 | E50: positiv = Nora hält/schuldet diesen Betrag
...
